<sdf version='1.7'>
  <world name='default'>
    <light name='sun' type='directional'>
      <cast_shadows>1</cast_shadows>
      <pose>0 0 10 0 -0 0</pose>
      <diffuse>0.8 0.8 0.8 1</diffuse>
      <specular>0.2 0.2 0.2 1</specular>
      <attenuation>
        <range>1000</range>
        <constant>0.9</constant>
        <linear>0.01</linear>
        <quadratic>0.001</quadratic>
      </attenuation>
      <direction>-0.5 0.1 -0.9</direction>
      <spot>
        <inner_angle>0</inner_angle>
        <outer_angle>0</outer_angle>
        <falloff>0</falloff>
      </spot>
    </light>
    <model name='ground_plane'>
      <static>1</static>
      <link name='link'>
        <collision name='collision'>
          <geometry>
            <plane>
              <normal>0 0 1</normal>
              <size>100 100</size>
            </plane>
          </geometry>
          <surface>
            <contact>
              <collide_bitmask>65535</collide_bitmask>
              <ode/>
            </contact>
            <friction>
              <ode>
                <mu>100</mu>
                <mu2>50</mu2>
              </ode>
              <torsional>
                <ode/>
              </torsional>
            </friction>
            <bounce/>
          </surface>
          <max_contacts>10</max_contacts>
        </collision>
        <visual name='visual'>
          <cast_shadows>0</cast_shadows>
          <geometry>
            <plane>
              <normal>0 0 1</normal>
              <size>100 100</size>
            </plane>
          </geometry>
          <material>
            <script>
              <uri>file://media/materials/scripts/gazebo.material</uri>
              <name>Gazebo/Grey</name>
            </script>
          </material>
        </visual>
        <self_collide>0</self_collide>
        <enable_wind>0</enable_wind>
        <kinematic>0</kinematic>
      </link>
    </model>
    <gravity>0 0 -9.8</gravity>
    <magnetic_field>6e-06 2.3e-05 -4.2e-05</magnetic_field>
    <atmosphere type='adiabatic'/>
    <physics type='ode'>
      <max_step_size>0.001</max_step_size>
      <real_time_factor>1</real_time_factor>
      <real_time_update_rate>1000</real_time_update_rate>
    </physics>
    <scene>
      <ambient>0.4 0.4 0.4 1</ambient>
      <background>0.7 0.7 0.7 1</background>
      <shadows>1</shadows>
    </scene>
    <audio>
      <device>default</device>
    </audio>
    <wind/>
    <spherical_coordinates>
      <surface_model>EARTH_WGS84</surface_model>
      <latitude_deg>0</latitude_deg>
      <longitude_deg>0</longitude_deg>
      <elevation>0</elevation>
      <heading_deg>0</heading_deg>
    </spherical_coordinates>
    <model name='my_robot'>
      <link name='base_link'>
        <inertial>
          <pose>-0.011075 -1.9e-05 0.095447 0 -0 0</pose>
          <mass>49.0268</mass>
          <inertia>
            <ixx>2.32103</ixx>
            <ixy>0.000242844</ixy>
            <ixz>0.0771565</ixz>
            <iyy>2.98841</iyy>
            <iyz>-7.01748e-05</iyz>
            <izz>2.19722</izz>
          </inertia>
        </inertial>
        <collision name='base_link_collision'>
          <pose>0 0 0 0 -0 0</pose>
          <geometry>
            <mesh>
              <scale>0.001 0.001 0.001</scale>
              <uri>/home/akshat/ros2WS/src/robot/meshes/base_link.stl</uri>
            </mesh>
          </geometry>
          <surface>
            <contact>
              <ode/>
            </contact>
            <friction>
              <ode>
                <mu>0.2</mu>
                <mu2>0.2</mu2>
              </ode>
              <torsional>
                <ode/>
              </torsional>
            </friction>
            <bounce/>
          </surface>
          <max_contacts>10</max_contacts>
        </collision>
        <collision name='base_link_fixed_joint_lump__gps_link_collision_1'>
          <pose>-0.06 0 0.07 0 -0 0</pose>
          <geometry>
            <box>
              <size>0.025 0.025 0.025</size>
            </box>
          </geometry>
          <surface>
            <contact>
              <ode/>
            </contact>
            <friction>
              <ode/>
              <torsional>
                <ode/>
              </torsional>
            </friction>
            <bounce/>
          </surface>
          <max_contacts>10</max_contacts>
        </collision>
        <collision name='base_link_fixed_joint_lump__imu_link_collision_2'>
          <pose>0 0 0.07 0 -0 0</pose>
          <geometry>
            <box>
              <size>0.051 0.051 0.051</size>
            </box>
          </geometry>
          <surface>
            <contact>
              <ode/>
            </contact>
            <friction>
              <ode/>
              <torsional>
                <ode/>
              </torsional>
            </friction>
            <bounce/>
          </surface>
          <max_contacts>10</max_contacts>
        </collision>
        <collision name='base_link_fixed_joint_lump__laser_link_collision_3'>
          <pose>0.2 0 0.15 0 -0 0</pose>
          <geometry>
            <box>
              <size>0.075 0.075 0.075</size>
            </box>
          </geometry>
          <surface>
            <contact>
              <ode/>
            </contact>
            <friction>
              <ode/>
              <torsional>
                <ode/>
              </torsional>
            </friction>
            <bounce/>
          </surface>
          <max_contacts>10</max_contacts>
        </collision>
        <collision name='base_link_fixed_joint_lump__zed2_tilt_head_link_collision_4'>
          <pose>0.25 0 0.02 0 -0.02 3.14159</pose>
          <geometry>
            <mesh>
              <scale>1 1 1</scale>
              <uri>/home/akshat/ros2WS/src/robot/meshes/zed2_base.dae</uri>
            </mesh>
          </geometry>
          <max_contacts>10</max_contacts>
          <surface>
            <contact>
              <ode/>
            </contact>
            <bounce/>
            <friction>
              <torsional>
                <ode/>
              </torsional>
              <ode/>
            </friction>
          </surface>
        </collision>
        <collision name='base_link_fixed_joint_lump__zed2_camera_center_collision_5'>
          <pose>0.250972 0 0.06859 0 0.052638 0</pose>
          <geometry>
            <mesh>
              <scale>1 1 1</scale>
              <uri>/home/akshat/ros2WS/src/robot/meshes/zed2.dae</uri>
            </mesh>
          </geometry>
          <max_contacts>10</max_contacts>
          <surface>
            <contact>
              <ode/>
            </contact>
            <bounce/>
            <friction>
              <torsional>
                <ode/>
              </torsional>
              <ode/>
            </friction>
          </surface>
        </collision>
        <visual name='base_link_visual'>
          <pose>0 0 0 0 -0 0</pose>
          <geometry>
            <mesh>
              <scale>0.001 0.001 0.001</scale>
              <uri>/home/akshat/ros2WS/src/robot/meshes/base_link.stl</uri>
            </mesh>
          </geometry>
          <material>
            <script>
              <name>Gazebo/Orange</name>
              <uri>file://media/materials/scripts/gazebo.material</uri>
            </script>
          </material>
        </visual>
        <visual name='base_link_fixed_joint_lump__gps_link_visual_1'>
          <pose>-0.06 0 0.07 0 -0 0</pose>
          <geometry>
            <box>
              <size>0.025 0.025 0.025</size>
            </box>
          </geometry>
        </visual>
        <visual name='base_link_fixed_joint_lump__imu_link_visual_2'>
          <pose>0 0 0.07 0 -0 0</pose>
          <geometry>
            <box>
              <size>0.051 0.051 0.051</size>
            </box>
          </geometry>
        </visual>
        <visual name='base_link_fixed_joint_lump__laser_link_visual_3'>
          <pose>0.2 0 0.15 0 -0 0</pose>
          <geometry>
            <mesh>
              <scale>1 1 1</scale>
              <uri>/home/akshat/ros2WS/src/robot/meshes/sick_scan.dae</uri>
            </mesh>
          </geometry>
        </visual>
        <visual name='base_link_fixed_joint_lump__zed2_tilt_head_link_visual_4'>
          <pose>0.25 0 0.02 0 -0.02 3.14159</pose>
          <geometry>
            <mesh>
              <scale>1 1 1</scale>
              <uri>/home/akshat/ros2WS/src/robot/meshes/zed2_base.dae</uri>
            </mesh>
          </geometry>
        </visual>
        <visual name='base_link_fixed_joint_lump__zed2_camera_center_visual_5'>
          <pose>0.250972 0 0.06859 0 0.052638 0</pose>
          <geometry>
            <mesh>
              <scale>1 1 1</scale>
              <uri>/home/akshat/ros2WS/src/robot/meshes/zed2.dae</uri>
            </mesh>
          </geometry>
        </visual>
        <self_collide>1</self_collide>
        <gravity>1</gravity>
        <sensor name='gps_sensor' type='gps'>
          <always_on>1</always_on>
          <update_rate>1</update_rate>
          <plugin name='gps_controller' filename='libgazebo_ros_gps_sensor.so'>
            <ros>
              <remapping>gps_controller/out:=gps</remapping>
            </ros>
            <frame_name>gps_link</frame_name>
          </plugin>
          <pose>-0.06 0 0.07 0 -0 0</pose>
          <gps/>
        </sensor>
        <sensor name='imu_sensor' type='imu'>
          <always_on>1</always_on>
          <update_rate>100</update_rate>
          <topic>imu_data</topic>
          <imu>
            <angular_velocity>
              <x>
                <noise type='gaussian'>
                  <mean>0</mean>
                  <stddev>0</stddev>
                </noise>
              </x>
              <y>
                <noise type='gaussian'>
                  <mean>0</mean>
                  <stddev>0</stddev>
                </noise>
              </y>
              <z>
                <noise type='gaussian'>
                  <mean>0</mean>
                  <stddev>0</stddev>
                </noise>
              </z>
            </angular_velocity>
            <linear_acceleration>
              <x>
                <noise type='gaussian'>
                  <mean>0</mean>
                  <stddev>0</stddev>
                </noise>
              </x>
              <y>
                <noise type='gaussian'>
                  <mean>0</mean>
                  <stddev>0</stddev>
                </noise>
              </y>
              <z>
                <noise type='gaussian'>
                  <mean>0</mean>
                  <stddev>0</stddev>
                </noise>
              </z>
            </linear_acceleration>
          </imu>
          <plugin name='bytes_imu' filename='libgazebo_ros_imu_sensor.so'>
            <ros>
              <namespace>imu</namespace>
              <remapping>~/out:=imu_data</remapping>
            </ros>
            <frameName>imu_link</frameName>
            <initial_orientation_as_reference>0</initial_orientation_as_reference>
          </plugin>
          <pose>0 0 0.07 0 -0 0</pose>
        </sensor>
        <sensor name='laser' type='ray'>
          <visualize>1</visualize>
          <update_rate>40</update_rate>
          <ray>
            <scan>
              <horizontal>
                <samples>1101</samples>
                <min_angle>-2.356</min_angle>
                <max_angle>2.356</max_angle>
                <resolution>1</resolution>
              </horizontal>
              <vertical>
                <samples>1</samples>
                <min_angle>0</min_angle>
                <max_angle>0</max_angle>
              </vertical>
            </scan>
            <range>
              <min>0.1</min>
              <max>10</max>
              <resolution>0.01</resolution>
            </range>
            <noise>
              <type>gaussian</type>
              <mean>0</mean>
              <stddev>0.01</stddev>
            </noise>
          </ray>
          <plugin name='laser_controller' filename='libgazebo_ros_ray_sensor.so'>
            <ros>
              <remapping>~/out:=scan</remapping>
            </ros>
            <output_type>sensor_msgs/LaserScan</output_type>
            <frame_name>laser_link</frame_name>
          </plugin>
          <pose>0.2 0 0.15 0 -0 0</pose>
        </sensor>
        <sensor name='zed2_left_raw_camera' type='camera'>
          <always_on>1</always_on>
          <update_rate>120</update_rate>
          <visualize>0</visualize>
          <camera name='zed2_left_raw'>
            <horizontal_fov>1.7633</horizontal_fov>
            <image>
              <width>1280</width>
              <height>720</height>
              <format>R8G8B8</format>
            </image>
            <clip>
              <near>0.02</near>
              <far>300</far>
            </clip>
            <noise>
              <type>gaussian</type>
              <mean>0</mean>
              <stddev>0.007</stddev>
            </noise>
            <distortion>
              <k1>-0.0436936</k1>
              <k2>0.0146165</k2>
              <p1>-0.00657332</p1>
              <p2>-0.0002169</p2>
              <k3>8.4328e-05</k3>
              <center>0.5 0.5</center>
            </distortion>
          </camera>
          <plugin name='camera_controller' filename='libgazebo_ros_camera.so'>
            <cameraName>zed2/left_raw</cameraName>
            <imageTopicName>image_raw_color</imageTopicName>
            <cameraInfoTopicName>camera_info</cameraInfoTopicName>
            <frameName>zed2_left_camera_optical_frame</frameName>
            <distortionK1>-0.043693598</distortionK1>
            <distortionK2>0.0146164996</distortionK2>
            <distortionT1>-0.006573319</distortionT1>
            <distortionT2>-0.000216900</distortionT2>
            <distortionK3>0.000084328</distortionK3>
            <CxPrime>648.5</CxPrime>
            <Cx>648.5</Cx>
            <Cy>366.8340148925781</Cy>
            <hackBaseline>0.0</hackBaseline>
          </plugin>
          <pose>0.250972 0.06 0.06859 0 0.052638 0</pose>
        </sensor>
        <sensor name='zed2_left_camera' type='depth'>
          <always_on>1</always_on>
          <update_rate>15</update_rate>
          <visualize>0</visualize>
          <camera name='zed2_left'>
            <horizontal_fov>1.7633</horizontal_fov>
            <image>
              <width>1280</width>
              <height>720</height>
              <format>R8G8B8</format>
            </image>
            <clip>
              <near>0.02</near>
              <far>300</far>
            </clip>
            <noise>
              <type>gaussian</type>
              <mean>0</mean>
              <stddev>0.007</stddev>
            </noise>
          </camera>
          <plugin name='camera_controller2' filename='libgazebo_ros_camera.so'>
            <cameraName>zed2</cameraName>
            <imageTopicName>left/image_rect_color</imageTopicName>
            <cameraInfoTopicName>left/camera_info</cameraInfoTopicName>
            <depthImageTopicName>depth/depth_registered</depthImageTopicName>
            <depthImageInfoTopicName>depth/camera_info</depthImageInfoTopicName>
            <pointCloudTopicName>point_cloud/cloud_registered</pointCloudTopicName>
            <pointCloudCutoff>0.3</pointCloudCutoff>
            <pointCloudCutoffMax>20.0</pointCloudCutoffMax>
            <frameName>zed2_left_camera_optical_frame</frameName>
            <baseline>0.12</baseline>
            <CxPrime>658.8206787109375</CxPrime>
            <Cx>658.8206787109375</Cx>
            <Cy>372.25787353515625</Cy>
            <hackBaseline>0.0</hackBaseline>
          </plugin>
          <pose>0.250972 0.06 0.06859 0 0.052638 0</pose>
        </sensor>
        <sensor name='zed2_right_raw_camera' type='camera'>
          <always_on>1</always_on>
          <update_rate>15</update_rate>
          <visualize>0</visualize>
          <camera name='zed2_right_raw'>
            <horizontal_fov>1.7633</horizontal_fov>
            <image>
              <width>1280</width>
              <height>720</height>
              <format>R8G8B8</format>
            </image>
            <clip>
              <near>0.02</near>
              <far>300</far>
            </clip>
            <noise>
              <type>gaussian</type>
              <mean>0</mean>
              <stddev>0.007</stddev>
            </noise>
            <distortion>
              <k1>-0.0409933</k1>
              <k2>0.00959359</k2>
              <p1>-0.00442985</p1>
              <p2>0.000192024</p2>
              <k3>-0.00032088</k3>
              <center>0.5 0.5</center>
            </distortion>
          </camera>
          <plugin name='camera_controller3' filename='libgazebo_ros_camera.so'>
            <cameraName>zed2/right_raw</cameraName>
            <imageTopicName>image_raw_color</imageTopicName>
            <cameraInfoTopicName>camera_info</cameraInfoTopicName>
            <frameName>zed2_right_camera_optical_frame</frameName>
            <distortionK1>-0.040993299</distortionK1>
            <distortionK2>0.009593590</distortionK2>
            <distortionT1>-0.004429849</distortionT1>
            <distortionT2>0.000192024</distortionT2>
            <distortionK3>-0.000320880</distortionK3>
            <CxPrime>659.3049926757812</CxPrime>
            <Cx>659.3049926757812</Cx>
            <Cy>371.39849853515625</Cy>
            <hackBaseline>0.12</hackBaseline>
          </plugin>
          <pose>0.250972 -0.06 0.06859 0 0.052638 0</pose>
        </sensor>
        <sensor name='zed2_right_camera' type='camera'>
          <always_on>1</always_on>
          <update_rate>15</update_rate>
          <visualize>0</visualize>
          <camera name='zed2_right'>
            <horizontal_fov>1.7633</horizontal_fov>
            <image>
              <width>1280</width>
              <height>720</height>
              <format>R8G8B8</format>
            </image>
            <clip>
              <near>0.02</near>
              <far>300</far>
            </clip>
            <noise>
              <type>gaussian</type>
              <mean>0</mean>
              <stddev>0.007</stddev>
            </noise>
          </camera>
          <plugin name='camera_controller4' filename='libgazebo_ros_camera.so'>
            <cameraName>zed2/right</cameraName>
            <imageTopicName>image_rect_color</imageTopicName>
            <cameraInfoTopicName>camera_info</cameraInfoTopicName>
            <frameName>zed2_right_camera_optical_frame</frameName>
            <CxPrime>658.8206787109375</CxPrime>
            <Cx>658.8206787109375</Cx>
            <Cy>372.25787353515625</Cy>
            <hackBaseline>0.12</hackBaseline>
          </plugin>
          <pose>0.250972 -0.06 0.06859 0 0.052638 0</pose>
        </sensor>
        <enable_wind>0</enable_wind>
        <kinematic>0</kinematic>
      </link>
      <joint name='joint_front_left' type='revolute'>
        <pose relative_to='base_link'>0.125 0.16 0.03 0 -0 0</pose>
        <parent>base_link</parent>
        <child>wheel_front_left_1</child>
        <axis>
          <xyz>0 1 0</xyz>
          <limit>
            <effort>10000</effort>
            <velocity>1000</velocity>
            <lower>-1e+16</lower>
            <upper>1e+16</upper>
          </limit>
          <dynamics>
            <spring_reference>0</spring_reference>
            <spring_stiffness>0</spring_stiffness>
          </dynamics>
        </axis>
      </joint>
      <link name='wheel_front_left_1'>
        <pose relative_to='joint_front_left'>0 0 0 0 -0 0</pose>
        <inertial>
          <pose>0 -0.009939 -0 0 -0 0</pose>
          <mass>0.552895</mass>
          <inertia>
            <ixx>0.001246</ixx>
            <ixy>0</ixy>
            <ixz>0</ixz>
            <iyy>0.002096</iyy>
            <iyz>0</iyz>
            <izz>0.001246</izz>
          </inertia>
        </inertial>
        <collision name='wheel_front_left_1_collision'>
          <pose>0 0 0 1.57 -0 0</pose>
          <geometry>
            <cylinder>
              <length>0.07</length>
              <radius>0.08</radius>
            </cylinder>
          </geometry>
          <surface>
            <contact>
              <ode/>
            </contact>
            <friction>
              <ode>
                <mu>0.2</mu>
                <mu2>0.2</mu2>
              </ode>
              <torsional>
                <ode/>
              </torsional>
            </friction>
            <bounce/>
          </surface>
          <max_contacts>10</max_contacts>
        </collision>
        <visual name='wheel_front_left_1_visual'>
          <pose>-0.01 0.005 -0.017 0 -0 0</pose>
          <geometry>
            <mesh>
              <scale>1 1 1</scale>
              <uri>/home/akshat/ros2WS/src/robot/meshes/wheel.dae</uri>
            </mesh>
          </geometry>
          <material>
            <script>
              <name>Gazebo/Silver</name>
              <uri>file://media/materials/scripts/gazebo.material</uri>
            </script>
          </material>
        </visual>
        <self_collide>1</self_collide>
        <enable_wind>0</enable_wind>
        <kinematic>0</kinematic>
      </link>
      <joint name='joint_front_right' type='revolute'>
        <pose relative_to='base_link'>0.125 -0.16 0.03 0 -0 0</pose>
        <parent>base_link</parent>
        <child>wheel_front_right_1</child>
        <axis>
          <xyz>0 1 0</xyz>
          <limit>
            <effort>10000</effort>
            <velocity>1000</velocity>
            <lower>-1e+16</lower>
            <upper>1e+16</upper>
          </limit>
          <dynamics>
            <spring_reference>0</spring_reference>
            <spring_stiffness>0</spring_stiffness>
          </dynamics>
        </axis>
      </joint>
      <link name='wheel_front_right_1'>
        <pose relative_to='joint_front_right'>0 0 0 0 -0 0</pose>
        <inertial>
          <pose>0 0.009939 0 0 -0 0</pose>
          <mass>0.552895</mass>
          <inertia>
            <ixx>0.001246</ixx>
            <ixy>0</ixy>
            <ixz>0</ixz>
            <iyy>0.002096</iyy>
            <iyz>0</iyz>
            <izz>0.001246</izz>
          </inertia>
        </inertial>
        <collision name='wheel_front_right_1_collision'>
          <pose>0 0 0 1.57 -0 0</pose>
          <geometry>
            <cylinder>
              <length>0.07</length>
              <radius>0.08</radius>
            </cylinder>
          </geometry>
          <surface>
            <contact>
              <ode/>
            </contact>
            <friction>
              <ode>
                <mu>0.2</mu>
                <mu2>0.2</mu2>
              </ode>
              <torsional>
                <ode/>
              </torsional>
            </friction>
            <bounce/>
          </surface>
          <max_contacts>10</max_contacts>
        </collision>
        <visual name='wheel_front_right_1_visual'>
          <pose>0.01 -0.005 -0.017 0 -0 3.14</pose>
          <geometry>
            <mesh>
              <scale>1 1 1</scale>
              <uri>/home/akshat/ros2WS/src/robot/meshes/wheel.dae</uri>
            </mesh>
          </geometry>
          <material>
            <script>
              <name>Gazebo/Silver</name>
              <uri>file://media/materials/scripts/gazebo.material</uri>
            </script>
          </material>
        </visual>
        <self_collide>1</self_collide>
        <enable_wind>0</enable_wind>
        <kinematic>0</kinematic>
      </link>
      <joint name='joint_rear_left' type='revolute'>
        <pose relative_to='base_link'>-0.125 0.16 0.03 0 -0 0</pose>
        <parent>base_link</parent>
        <child>wheel_rear_left_1</child>
        <axis>
          <xyz>0 1 0</xyz>
          <limit>
            <effort>10000</effort>
            <velocity>1000</velocity>
            <lower>-1e+16</lower>
            <upper>1e+16</upper>
          </limit>
          <dynamics>
            <spring_reference>0</spring_reference>
            <spring_stiffness>0</spring_stiffness>
          </dynamics>
        </axis>
      </joint>
      <link name='wheel_rear_left_1'>
        <pose relative_to='joint_rear_left'>0 0 0 0 -0 0</pose>
        <inertial>
          <pose>0 -0.009939 -0 0 -0 0</pose>
          <mass>0.552895</mass>
          <inertia>
            <ixx>0.001246</ixx>
            <ixy>0</ixy>
            <ixz>0</ixz>
            <iyy>0.002096</iyy>
            <iyz>0</iyz>
            <izz>0.001246</izz>
          </inertia>
        </inertial>
        <collision name='wheel_rear_left_1_collision'>
          <pose>0 0 0 1.57 -0 0</pose>
          <geometry>
            <cylinder>
              <length>0.07</length>
              <radius>0.08</radius>
            </cylinder>
          </geometry>
          <surface>
            <contact>
              <ode/>
            </contact>
            <friction>
              <ode>
                <mu>0.2</mu>
                <mu2>0.2</mu2>
              </ode>
              <torsional>
                <ode/>
              </torsional>
            </friction>
            <bounce/>
          </surface>
          <max_contacts>10</max_contacts>
        </collision>
        <visual name='wheel_rear_left_1_visual'>
          <pose>-0.01 0.005 -0.017 0 -0 0</pose>
          <geometry>
            <mesh>
              <scale>1 1 1</scale>
              <uri>/home/akshat/ros2WS/src/robot/meshes/wheel.dae</uri>
            </mesh>
          </geometry>
          <material>
            <script>
              <name>Gazebo/Silver</name>
              <uri>file://media/materials/scripts/gazebo.material</uri>
            </script>
          </material>
        </visual>
        <self_collide>1</self_collide>
        <enable_wind>0</enable_wind>
        <kinematic>0</kinematic>
      </link>
      <joint name='joint_rear_right' type='revolute'>
        <pose relative_to='base_link'>-0.125 -0.16 0.03 0 -0 0</pose>
        <parent>base_link</parent>
        <child>wheel_rear_right_1</child>
        <axis>
          <xyz>0 1 0</xyz>
          <limit>
            <effort>10000</effort>
            <velocity>1000</velocity>
            <lower>-1e+16</lower>
            <upper>1e+16</upper>
          </limit>
          <dynamics>
            <spring_reference>0</spring_reference>
            <spring_stiffness>0</spring_stiffness>
          </dynamics>
        </axis>
      </joint>
      <link name='wheel_rear_right_1'>
        <pose relative_to='joint_rear_right'>0 0 0 0 -0 0</pose>
        <inertial>
          <pose>0 0.009939 0 0 -0 0</pose>
          <mass>0.552895</mass>
          <inertia>
            <ixx>0.001246</ixx>
            <ixy>0</ixy>
            <ixz>0</ixz>
            <iyy>0.002096</iyy>
            <iyz>0</iyz>
            <izz>0.001246</izz>
          </inertia>
        </inertial>
        <collision name='wheel_rear_right_1_collision'>
          <pose>0 0 0 1.57 -0 0</pose>
          <geometry>
            <cylinder>
              <length>0.07</length>
              <radius>0.08</radius>
            </cylinder>
          </geometry>
          <surface>
            <contact>
              <ode/>
            </contact>
            <friction>
              <ode>
                <mu>0.2</mu>
                <mu2>0.2</mu2>
              </ode>
              <torsional>
                <ode/>
              </torsional>
            </friction>
            <bounce/>
          </surface>
          <max_contacts>10</max_contacts>
        </collision>
        <visual name='wheel_rear_right_1_visual'>
          <pose>0.01 -0.005 -0.017 0 -0 3.14</pose>
          <geometry>
            <mesh>
              <scale>1 1 1</scale>
              <uri>/home/akshat/ros2WS/src/robot/meshes/wheel.dae</uri>
            </mesh>
          </geometry>
          <material>
            <script>
              <name>Gazebo/Silver</name>
              <uri>file://media/materials/scripts/gazebo.material</uri>
            </script>
          </material>
        </visual>
        <self_collide>1</self_collide>
        <enable_wind>0</enable_wind>
        <kinematic>0</kinematic>
      </link>
      <static>0</static>
      <plugin name='skid_steer_drive_controller' filename='libgazebo_ros_diff_drive.so'>
        <num_wheel_pairs>2</num_wheel_pairs>
        <left_joint>joint_front_left</left_joint>
        <left_joint>joint_rear_left</left_joint>
        <right_joint>joint_front_right</right_joint>
        <right_joint>joint_rear_right</right_joint>
        <robot_base_frame>base_link</robot_base_frame>
        <max_wheel_torque>100.0</max_wheel_torque>
        <max_wheel_acceleration>10.0</max_wheel_acceleration>
        <wheelSeparation>1.2</wheelSeparation>
        <wheelDiameter>0.80</wheelDiameter>
        <ros>
          <namespace>/</namespace>
          <argument>/cmd_vel:=cmd_vel</argument>
          <argument>/odom:=odom</argument>
        </ros>
        <publish_odom>1</publish_odom>
        <publish_odom_tf>1</publish_odom_tf>
        <update_rate>30.0</update_rate>
      </plugin>
      <pose>0 0 1.5 0 -0 0</pose>
    </model>
    <light name='user_spot_light_0' type='spot'>
      <pose>0.937742 14.7667 1 0 -0 0</pose>
      <diffuse>0.5 0.5 0.5 1</diffuse>
      <specular>0.1 0.1 0.1 1</specular>
      <direction>0 0 -1</direction>
      <attenuation>
        <range>20</range>
        <constant>0.5</constant>
        <linear>0.01</linear>
        <quadratic>0.001</quadratic>
      </attenuation>
      <cast_shadows>0</cast_shadows>
      <spot>
        <inner_angle>0.6</inner_angle>
        <outer_angle>1</outer_angle>
        <falloff>1</falloff>
      </spot>
    </light>
    <model name='unit_sphere'>
      <pose>-4.14623 3.81367 0.5 0 -0 0</pose>
      <link name='link'>
        <inertial>
          <mass>1</mass>
          <inertia>
            <ixx>0.1</ixx>
            <ixy>0</ixy>
            <ixz>0</ixz>
            <iyy>0.1</iyy>
            <iyz>0</iyz>
            <izz>0.1</izz>
          </inertia>
          <pose>0 0 0 0 -0 0</pose>
        </inertial>
        <collision name='collision'>
          <geometry>
            <sphere>
              <radius>0.5</radius>
            </sphere>
          </geometry>
          <max_contacts>10</max_contacts>
          <surface>
            <contact>
              <ode/>
            </contact>
            <bounce/>
            <friction>
              <torsional>
                <ode/>
              </torsional>
              <ode/>
            </friction>
          </surface>
        </collision>
        <visual name='visual'>
          <geometry>
            <sphere>
              <radius>0.5</radius>
            </sphere>
          </geometry>
          <material>
            <script>
              <name>Gazebo/Grey</name>
              <uri>file://media/materials/scripts/gazebo.material</uri>
            </script>
          </material>
        </visual>
        <self_collide>0</self_collide>
        <enable_wind>0</enable_wind>
        <kinematic>0</kinematic>
      </link>
    </model>
    <model name='unit_sphere_0'>
      <pose>-4.58442 2.1594 0.5 0 -0 0</pose>
      <link name='link'>
        <inertial>
          <mass>1</mass>
          <inertia>
            <ixx>0.1</ixx>
            <ixy>0</ixy>
            <ixz>0</ixz>
            <iyy>0.1</iyy>
            <iyz>0</iyz>
            <izz>0.1</izz>
          </inertia>
          <pose>0 0 0 0 -0 0</pose>
        </inertial>
        <collision name='collision'>
          <geometry>
            <sphere>
              <radius>0.5</radius>
            </sphere>
          </geometry>
          <max_contacts>10</max_contacts>
          <surface>
            <contact>
              <ode/>
            </contact>
            <bounce/>
            <friction>
              <torsional>
                <ode/>
              </torsional>
              <ode/>
            </friction>
          </surface>
        </collision>
        <visual name='visual'>
          <geometry>
            <sphere>
              <radius>0.5</radius>
            </sphere>
          </geometry>
          <material>
            <script>
              <name>Gazebo/Grey</name>
              <uri>file://media/materials/scripts/gazebo.material</uri>
            </script>
          </material>
        </visual>
        <self_collide>0</self_collide>
        <enable_wind>0</enable_wind>
        <kinematic>0</kinematic>
      </link>
    </model>
    <model name='unit_cylinder'>
      <pose>-2.73129 4.53514 0.5 0 -0 0</pose>
      <link name='link'>
        <inertial>
          <mass>1</mass>
          <inertia>
            <ixx>0.145833</ixx>
            <ixy>0</ixy>
            <ixz>0</ixz>
            <iyy>0.145833</iyy>
            <iyz>0</iyz>
            <izz>0.125</izz>
          </inertia>
          <pose>0 0 0 0 -0 0</pose>
        </inertial>
        <collision name='collision'>
          <geometry>
            <cylinder>
              <radius>0.5</radius>
              <length>1</length>
            </cylinder>
          </geometry>
          <max_contacts>10</max_contacts>
          <surface>
            <contact>
              <ode/>
            </contact>
            <bounce/>
            <friction>
              <torsional>
                <ode/>
              </torsional>
              <ode/>
            </friction>
          </surface>
        </collision>
        <visual name='visual'>
          <geometry>
            <cylinder>
              <radius>0.5</radius>
              <length>1</length>
            </cylinder>
          </geometry>
          <material>
            <script>
              <name>Gazebo/Grey</name>
              <uri>file://media/materials/scripts/gazebo.material</uri>
            </script>
          </material>
        </visual>
        <self_collide>0</self_collide>
        <enable_wind>0</enable_wind>
        <kinematic>0</kinematic>
      </link>
    </model>
    <state world_name='default'>
      <sim_time>197 640000000</sim_time>
      <real_time>203 712634872</real_time>
      <wall_time>1724481704 533027926</wall_time>
      <iterations>197640</iterations>
      <model name='ground_plane'>
        <pose>0 0 0 0 -0 0</pose>
        <scale>1 1 1</scale>
        <link name='link'>
          <pose>0 0 0 0 -0 0</pose>
          <velocity>0 0 0 0 -0 0</velocity>
          <acceleration>0 0 0 0 -0 0</acceleration>
          <wrench>0 0 0 0 -0 0</wrench>
        </link>
      </model>
      <model name='my_robot'>
        <pose>0.10184 -0.818747 0.050018 9e-06 -1.4e-05 0.261487</pose>
        <scale>1 1 1</scale>
        <link name='base_link'>
          <pose>0.10184 -0.818747 0.050018 9e-06 -1.4e-05 0.261487</pose>
          <velocity>0.00106 -0.004048 0.004861 -4.1e-05 -2.8e-05 0.001326</velocity>
          <acceleration>0.018176 -0.069974 9.72178 -0.084507 -0.060888 -0.008695</acceleration>
          <wrench>0.8911 -3.43062 476.628 0 -0 0</wrench>
        </link>
        <link name='wheel_front_left_1'>
          <pose>0.181227 -0.631867 0.080024 0.0002 -0.203856 0.261441</pose>
          <velocity>0.000628 -0.003015 0.005292 0.036564 0.007591 0.000203</velocity>
          <acceleration>-0.364393 1.77033 9.84314 -1.84897 0.216856 -2.25516</acceleration>
          <wrench>-0.201471 0.978805 5.44222 0 -0 0</wrench>
        </link>
        <link name='wheel_front_right_1'>
          <pose>0.263952 -0.94099 0.080023 0.000206 0.130746 0.261516</pose>
          <velocity>0.000968 -0.003044 0.005703 0.03731 0.011297 0.001661</velocity>
          <acceleration>-0.491096 1.49541 12.1806 1.16105 -1.49737 0.659535</acceleration>
          <wrench>-0.271525 0.826807 6.73457 0 -0 0</wrench>
        </link>
        <link name='wheel_rear_left_1'>
          <pose>-0.060275 -0.696497 0.080023 0.000231 -0.202139 0.261435</pose>
          <velocity>0.000751 -0.003472 0.005774 0.042427 0.009186 0.00016</velocity>
          <acceleration>-0.290532 1.49925 10.6852 -2.46125 -1.56821 -2.34144</acceleration>
          <wrench>-0.160634 0.828925 5.90782 0 -0 0</wrench>
        </link>
        <link name='wheel_rear_right_1'>
          <pose>0.02245 -1.00562 0.080022 0.000229 0.134714 0.26152</pose>
          <velocity>0.001068 -0.003393 0.006281 0.041703 0.012535 0.001671</velocity>
          <acceleration>-0.464696 1.44012 13.427 0.710137 1.22046 -2.4611</acceleration>
          <wrench>-0.256928 0.796237 7.42372 0 -0 0</wrench>
        </link>
      </model>
      <model name='unit_cylinder'>
        <pose>-2.73129 4.53514 0.499997 3e-06 4e-06 -0</pose>
        <scale>1 1 1</scale>
        <link name='link'>
          <pose>-2.73129 4.53514 0.499997 3e-06 4e-06 -0</pose>
          <velocity>0 0 0 0 -0 0</velocity>
          <acceleration>0 0 -9.8 0 -0 0</acceleration>
          <wrench>0 0 -9.8 0 -0 0</wrench>
        </link>
      </model>
      <model name='unit_sphere'>
        <pose>-4.14623 3.81367 0.5 0 -0 0</pose>
        <scale>1 1 1</scale>
        <link name='link'>
          <pose>-4.14623 3.81367 0.5 0 -0 0</pose>
          <velocity>0 0 0 0 -0 0</velocity>
          <acceleration>0 0 0 0 -0 0</acceleration>
          <wrench>0 0 0 0 -0 0</wrench>
        </link>
      </model>
      <model name='unit_sphere_0'>
        <pose>-4.58442 2.1594 0.5 0 -0 0</pose>
        <scale>1 1 1</scale>
        <link name='link'>
          <pose>-4.58442 2.1594 0.5 0 -0 0</pose>
          <velocity>0 0 0 0 -0 0</velocity>
          <acceleration>0 0 0 0 -0 0</acceleration>
          <wrench>0 0 0 0 -0 0</wrench>
        </link>
      </model>
      <light name='sun'>
        <pose>0 0 10 0 -0 0</pose>
      </light>
      <light name='user_spot_light_0'>
        <pose>0.937742 14.7667 1 0 -0 0</pose>
      </light>
    </state>
    <gui fullscreen='0'>
      <camera name='user_camera'>
        <pose>-32.3791 -0.817896 41.4509 0 1.02364 0.260195</pose>
        <view_controller>orbit</view_controller>
        <projection_type>perspective</projection_type>
      </camera>
    </gui>
  </world>
</sdf>
